[2024-03-25T14:52:55.314+0000] {taskinstance.py:1957} INFO - Dependencies all met for dep_context=non-requeueable deps ti=<TaskInstance: mysql_sample_dag.mysql_query_1 manual__2024-03-25T14:52:55.097447+00:00 [queued]>
[2024-03-25T14:52:55.318+0000] {taskinstance.py:1957} INFO - Dependencies all met for dep_context=requeueable deps ti=<TaskInstance: mysql_sample_dag.mysql_query_1 manual__2024-03-25T14:52:55.097447+00:00 [queued]>
[2024-03-25T14:52:55.319+0000] {taskinstance.py:2171} INFO - Starting attempt 1 of 1
[2024-03-25T14:52:55.326+0000] {taskinstance.py:2192} INFO - Executing <Task(MySqlOperator): mysql_query_1> on 2024-03-25 14:52:55.097447+00:00
[2024-03-25T14:52:55.329+0000] {standard_task_runner.py:60} INFO - Started process 229 to run task
[2024-03-25T14:52:55.331+0000] {standard_task_runner.py:87} INFO - Running: ['***', 'tasks', 'run', 'mysql_sample_dag', 'mysql_query_1', 'manual__2024-03-25T14:52:55.097447+00:00', '--job-id', '3', '--raw', '--subdir', 'DAGS_FOLDER/mysqltest.py', '--cfg-path', '/tmp/tmp7np5a9un']
[2024-03-25T14:52:55.333+0000] {standard_task_runner.py:88} INFO - Job 3: Subtask mysql_query_1
[2024-03-25T14:52:55.366+0000] {task_command.py:423} INFO - Running <TaskInstance: mysql_sample_dag.mysql_query_1 manual__2024-03-25T14:52:55.097447+00:00 [running]> on host 999def8209c6
[2024-03-25T14:52:55.411+0000] {taskinstance.py:2481} INFO - Exporting env vars: AIRFLOW_CTX_DAG_OWNER='***' AIRFLOW_CTX_DAG_ID='mysql_sample_dag' AIRFLOW_CTX_TASK_ID='mysql_query_1' AIRFLOW_CTX_EXECUTION_DATE='2024-03-25T14:52:55.097447+00:00' AIRFLOW_CTX_TRY_NUMBER='1' AIRFLOW_CTX_DAG_RUN_ID='manual__2024-03-25T14:52:55.097447+00:00'
[2024-03-25T14:52:55.411+0000] {sql.py:276} INFO - Executing: select * from dbtdb.test
[2024-03-25T14:52:55.412+0000] {connection.py:473} ERROR - Unable to retrieve connection from secrets backend (LocalFilesystemBackend). Checking subsequent secrets backend.
Traceback (most recent call last):
  File "/home/airflow/.local/lib/python3.8/site-packages/airflow/models/connection.py", line 468, in get_connection_from_secrets
    conn = secrets_backend.get_connection(conn_id=conn_id)
  File "/home/airflow/.local/lib/python3.8/site-packages/airflow/secrets/local_filesystem.py", line 316, in get_connection
    if conn_id in self._local_connections:
  File "/home/airflow/.local/lib/python3.8/site-packages/airflow/secrets/local_filesystem.py", line 313, in _local_connections
    return load_connections_dict(self.connections_file)
  File "/home/airflow/.local/lib/python3.8/site-packages/airflow/secrets/local_filesystem.py", line 265, in load_connections_dict
    secrets: dict[str, Any] = _parse_secret_file(file_path)
  File "/home/airflow/.local/lib/python3.8/site-packages/airflow/secrets/local_filesystem.py", line 162, in _parse_secret_file
    raise AirflowException(
airflow.exceptions.AirflowException: File /opt/secrets/connections.yaml was not found. Check the configuration of your Secrets backend.
[2024-03-25T14:52:55.424+0000] {taskinstance.py:2699} ERROR - Task failed with exception
Traceback (most recent call last):
  File "/home/airflow/.local/lib/python3.8/site-packages/airflow/models/taskinstance.py", line 433, in _execute_task
    result = execute_callable(context=context, **execute_callable_kwargs)
  File "/home/airflow/.local/lib/python3.8/site-packages/airflow/providers/common/sql/operators/sql.py", line 277, in execute
    hook = self.get_db_hook()
  File "/home/airflow/.local/lib/python3.8/site-packages/airflow/providers/common/sql/operators/sql.py", line 188, in get_db_hook
    return self._hook
  File "/usr/local/lib/python3.8/functools.py", line 967, in __get__
    val = self.func(instance)
  File "/home/airflow/.local/lib/python3.8/site-packages/airflow/providers/common/sql/operators/sql.py", line 150, in _hook
    conn = BaseHook.get_connection(conn_id)
  File "/home/airflow/.local/lib/python3.8/site-packages/airflow/hooks/base.py", line 82, in get_connection
    conn = Connection.get_connection_from_secrets(conn_id)
  File "/home/airflow/.local/lib/python3.8/site-packages/airflow/models/connection.py", line 479, in get_connection_from_secrets
    raise AirflowNotFoundException(f"The conn_id `{conn_id}` isn't defined")
airflow.exceptions.AirflowNotFoundException: The conn_id `mysql_conn` isn't defined
[2024-03-25T14:52:55.426+0000] {taskinstance.py:1138} INFO - Marking task as FAILED. dag_id=mysql_sample_dag, task_id=mysql_query_1, execution_date=20240325T145255, start_date=20240325T145255, end_date=20240325T145255
[2024-03-25T14:52:55.432+0000] {standard_task_runner.py:107} ERROR - Failed to execute job 3 for task mysql_query_1 (The conn_id `mysql_conn` isn't defined; 229)
[2024-03-25T14:52:55.463+0000] {local_task_job_runner.py:234} INFO - Task exited with return code 1
[2024-03-25T14:52:55.474+0000] {taskinstance.py:3281} INFO - 0 downstream tasks scheduled from follow-on schedule check
